<?xml version='1.0'?>
<sdf version='1.7'>
    <model name="exort">
        <static>false</static>

<!-- CHASSIS -->

        <link name="chassis">
            <pose>0 0 0.1 0 0 0</pose>
            <collision name="chassis_collision">
                <geometry>
                    <box>
                        <size>0.4 0.4 0.2</size>
                    </box>
                </geometry>
            </collision>
            <visual name="chassis_visual">
                <geometry>
                    <box>
                        <size>0.4 0.4 0.2</size>
                    </box>
                </geometry>
            </visual>
            <inertial>
                <mass value="1"/>
                <inertia ixx="0.0167" ixy="0.0" ixz="0.0" iyx="0.0" iyy="0.0167" iyz="0.0" izx="0.0" izy="0.0" izz="0.0267"/>
            </inertial>
        </link>

<!-- WHEELS -->

        <link name="front_left_wheel">
            <pose>0.2 0.2 0.05 0 0 0</pose>
            <collision name="flw_collision">
                <geometry>
                    <cylinder>
                        <radius>0.12</radius>
                        <length>0.8</length>
                    </cylinder>
                </geometry>
            </collision>
            <visual name="flw_visual">
                <geometry>
                    <cylinder>
                        <radius>0.12</radius>
                        <length>0.8</length>
                    </cylinder>
                </geometry>
            </visual>
            <inertial>
                <mass value="0.1"/>
                <inertia ixx="0.0057" ixy="0.0" ixz="0.0" iyx="0.0" iyy="0.0057" iyz="0.0" izx="0.0" izy="0.0" izz="0.00072"/>
            </inertial>
        </link>

        <link name="front_right_wheel">
            <pose>0.2 -0.2 0.05 0 0 0</pose>
            <collision name="frw_collision">
                <geometry>
                    <cylinder>
                        <radius>0.12</radius>
                        <length>0.8</length>
                    </cylinder>
                </geometry>
            </collision>
            <visual name="frw_visual">
                <geometry>
                    <cylinder>
                        <radius>0.12</radius>
                        <length>0.8</length>
                    </cylinder>
                </geometry>
            </visual>
            <inertial>
                <mass value="0.1"/>
                <inertia ixx="0.0057" ixy="0.0" ixz="0.0" iyx="0.0" iyy="0.0057" iyz="0.0" izx="0.0" izy="0.0" izz="0.00072"/>
            </inertial>
        </link>

        <link name="back_left_wheel">
            <pose>-0.2 0.2 0.05 0 0 0</pose>
            <collision name="blw_collision">
                <geometry>
                    <cylinder>
                        <radius>0.12</radius>
                        <length>0.8</length>
                    </cylinder>
                </geometry>
            </collision>
            <visual name="blw_visual">
                <geometry>
                    <cylinder>
                        <radius>0.12</radius>
                        <length>0.8</length>
                    </cylinder>
                </geometry>
            </visual>
            <inertial>
                <mass value="0.1"/>
                <inertia ixx="0.0057" ixy="0.0" ixz="0.0" iyx="0.0" iyy="0.0057" iyz="0.0" izx="0.0" izy="0.0" izz="0.00072"/>
            </inertial>
        </link>

        <link name="back_right_wheel">
            <pose>-0.2 -0.2 0.05 0 0 0</pose>
            <collision name="brw_collision">
                <geometry>
                    <cylinder>
                        <radius>0.12</radius>
                        <length>0.8</length>
                    </cylinder>
                </geometry>
            </collision>
            <visual name="brw_visual">
                <geometry>
                    <cylinder>
                        <radius>0.12</radius>
                        <length>0.8</length>
                    </cylinder>
                </geometry>
            </visual>
            <inertial>
                <mass value="0.1"/>
                <inertia ixx="0.0057" ixy="0.0" ixz="0.0" iyx="0.0" iyy="0.0057" iyz="0.0" izx="0.0" izy="0.0" izz="0.00072"/>
            </inertial>
        </link>

<!-- JOINTS -->

        <joint name="front_left_wheel_joint" type="revolute">
                <pose>0 0 -0.03 0 0 0</pose>
                <child>front_left_wheel</child>
                <parent>chassis</parent>
                <axis>
                <xyz>1 0 0</xyz>
                </axis>
        </joint>

        <joint name="front_right_wheel_joint" type="revolute">
                <pose>0 0 -0.03 0 0 0</pose>
                <child>front_right_wheel</child>
                <parent>chassis</parent>
                <axis>
                <xyz>1 0 0</xyz>
                </axis>
        </joint>

        <joint name="back_left_wheel_joint" type="revolute">
                <pose>0 0 -0.03 0 0 0</pose>
                <child>back_left_wheel</child>
                <parent>chassis</parent>
                <axis>
                <xyz>1 0 0</xyz>
                </axis>
        </joint>

        <joint name="back_right_wheel_joint" type="revolute">
                <pose>0 0 -0.03 0 0 0</pose>
                <child>back_right_wheel</child>
                <parent>chassis</parent>
                <axis>
                <xyz>1 0 0</xyz>
                </axis>
        </joint>
    </model>
</sdf>