<?xml version='1.0'?>


<robot xmlns:xacro="http://www.ros.org/wiki/xacro" name="exort">
  <!-- Chassis -->
  <link name="chassis">
    <inertial>
      <origin xyz="0 0 0.1" rpy="0 0 0"/>
      <mass value="1.0"/>
      <inertia ixx="0.0167" ixy="0.0" ixz="0.0" iyy="0.0167" iyz="0.0" izz="0.0267"/>
    </inertial>
    <visual>
      <origin xyz="0 0 0" rpy="0 0 0"/>
      <geometry>
        <box size="0.4 0.4 0.2"/>
      </geometry>
    </visual>
    <collision>
      <origin xyz="0 0 0" rpy="0 0 0"/>
      <geometry>
        <box size="0.4 0.4 0.2"/>
      </geometry>
    </collision>
  </link>

  <xacro:macro name="wheel" params="name x y">
    <link name="${name}">
      <inertial>
        <origin xyz="0 0 0" rpy="0 0 0"/>
        <mass value="0.1"/>
        <inertia ixx="0.0057" ixy="0.0" ixz="0.0" iyy="0.0057" iyz="0.0" izz="0.00072"/>
      </inertial>
      <visual>
        <origin xyz="0 0 0" rpy="0 0 0"/>
        <geometry>
          <cylinder radius="0.12" length="0.08"/>
        </geometry>
      </visual>
      <collision>
        <origin xyz="0 0 0" rpy="0 0 0"/>
        <geometry>
          <cylinder radius="0.12" length="0.08"/>
        </geometry>
      </collision>
    </link>

    <joint name="${name}_joint" type="revolute">
      <origin xyz="${x} ${y} 0.05" rpy="0 0 0"/>
      <parent link="chassis"/>
      <child link="${name}"/>
      <axis xyz="1 0 0"/>
    </joint>
  </xacro:macro>

  <!-- Wheels -->
  <xacro:wheel name="front_left_wheel" x="0.2" y="0.2"/>
  <xacro:wheel name="front_right_wheel" x="0.2" y="-0.2"/>
  <xacro:wheel name="back_left_wheel" x="-0.2" y="0.2"/>
  <xacro:wheel name="back_right_wheel" x="-0.2" y="-0.2"/>
</robot>
